Workbook
Name Slicer_Delivery_Status: #N/A
Name Slicer_Month: #N/A
Name Slicer_Payment_Method: #N/A
Name Slicer_Payment_Method1: #N/A
Name Slicer_Product_Category: #N/A
Name Slicer_Region: #N/A

Sheet AmazonSales_RawData
A1: Order ID | B1: Order Date | C1: Delivery Date | D1: Cancel Date | E1: Customer ID | F1: Product ID | G1: Region | H1: Sale Price/Unit | I1: Quantity | J1: Total Amount | K1: Payment Method | L1: Delivery Status | M1: Fulfillment Partner
A2: ORD0001 | B2: 12/31/2023 | D2: 1/2/2024 | E2: CUST021 | F2: PROD012 | G2: North | H2: 44 | I2: 1 | J2: 44 | K2: Apple Pay | L2: Cancelled | M2: DHL
A3: ORD0002 | B3: 2/22/2023 | C3: 2/24/2023 | E3: CUST029 | F3: PROD018 | G3: East | H3: 96 | I3: 4 | J3: 384 | K3: Credit Card | L3: Delivered | M3: DHL
A4: ORD0003 | B4: 10/11/2023 | E4: CUST021 | F4: PROD013 | G4: South | H4: 194 | I4: 4 | J4: 776 | K4: Credit Card | L4: In Transit | M4: USPS
A5: ORD0004 | B5: 5/5/2023 | D5: 5/11/2023 | E5: CUST044 | F5: PROD013 | G5: North | H5: 196 | I5: 3 | J5: 588 | K5: PayPal | L5: Cancelled | M5: UPS
A6: ORD0005 | B6: 2/2/2023 | C6: 2/5/2023 | E6: CUST027 | F6: PROD010 | G6: North | H6: 59 | I6: 1 | J6: 59 | K6: PayPal | L6: Delivered | M6: Amazon Logistics
A7: ORD0006 | B7: 11/1/2023 | D7: 11/2/2023 | E7: CUST009 | F7: PROD010 | G7: North | H7: 58 | I7: 4 | J7: 232 | K7: Amazon Pay | L7: Cancelled | M7: DHL
A8: ORD0007 | B8: 8/14/2023 | D8: 8/18/2023 | E8: CUST042 | F8: PROD020 | G8: Central | H8: 105 | I8: 3 | J8: 315 | K8: Debit Card | L8: Cancelled | M8: DHL
A9: ORD0008 | B9: 4/1/2023 | D9: 4/6/2023 | E9: CUST019 | F9: PROD021 | G9: West | H9: 37 | I9: 5 | J9: 185 | K9: PayPal | L9: Cancelled | M9: DHL
A10: ORD0009 | B10: 7/21/2023 | E10: CUST013 | F10: PROD019 | G10: Central | H10: 44 | I10: 2 | J10: 88 | K10: Credit Card | L10: In Transit | M10: Amazon Logistics
A11: ORD0010 | B11: 12/29/2023 | E11: CUST019 | F11: PROD003 | G11: South | H11: 141 | I11: 4 | J11: 564 | K11: Debit Card | L11: In Transit | M11: DHL
A12: ORD0011 | B12: 5/4/2023 | D12: 5/8/2023 | E12: CUST046 | F12: PROD014 | G12: South | H12: 249 | I12: 1 | J12: 249 | K12: Amazon Pay | L12: Cancelled | M12: USPS
A13: ORD0012 | B13: 7/25/2023 | E13: CUST045 | F13: PROD014 | G13: Central | H13: 247 | I13: 3 | J13: 741 | K13: Amazon Pay | L13: In Transit | M13: FedEx
A14: ORD0013 | B14: 2/25/2023 | D14: 2/28/2023 | E14: CUST023 | F14: PROD006 | G14: Central | H14: 96 | I14: 1 | J14: 96 | K14: Apple Pay | L14: Cancelled | M14: Amazon Logistics
A15: ORD0014 | B15: 2/24/2023 | D15: 2/25/2023 | E15: CUST033 | F15: PROD017 | G15: West | H15: 74 | I15: 5 | J15: 370 | K15: Apple Pay | L15: Cancelled | M15: Amazon Logistics
A16: ORD0015 | B16: 8/26/2023 | D16: 9/2/2023 | E16: CUST033 | F16: PROD005 | G16: South | H16: 27 | I16: 1 | J16: 27 | K16: Credit Card | L16: Cancelled | M16: Amazon Logistics
A17: ORD0016 | B17: 2/13/2023 | E17: CUST047 | F17: PROD005 | G17: South | H17: 27 | I17: 3 | J17: 81 | K17: Debit Card | L17: In Transit | M17: Amazon Logistics
A18: ORD0017 | B18: 6/28/2023 | C18: 7/1/2023 | E18: CUST045 | F18: PROD015 | G18: East | H18: 21 | I18: 3 | J18: 63 | K18: Credit Card | L18: Delivered | M18: DHL
A19: ORD0018 | B19: 11/28/2023 | E19: CUST011 | F19: PROD008 | G19: West | H19: 70 | I19: 5 | J19: 350 | K19: PayPal | L19: In Transit | M19: Amazon Logistics
A20: ORD0019 | B20: 8/25/2023 | E20: CUST041 | F20: PROD006 | G20: South | H20: 94 | I20: 4 | J20: 376 | K20: Credit Card | L20: In Transit | M20: USPS
A21: ORD0020 | B21: 4/12/2023 | E21: CUST025 | F21: PROD001 | G21: North | H21: 813 | I21: 2 | J21: 1626 | K21: Credit Card | L21: In Transit | M21: FedEx
A22: ORD0021 | B22: 10/2/2023 | E22: CUST013 | F22: PROD015 | G22: Central | H22: 21 | I22: 4 | J22: 84 | K22: PayPal | L22: In Transit | M22: Amazon Logistics
A23: ORD0022 | B23: 11/9/2023 | E23: CUST023 | F23: PROD012 | G23: West | H23: 46 | I23: 5 | J23: 230 | K23: PayPal | L23: In Transit | M23: USPS
A24: ORD0023 | B24: 2/13/2023 | D24: 2/14/2023 | E24: CUST016 | F24: PROD010 | G24: West | H24: 58 | I24: 3 | J24: 174 | K24: Amazon Pay | L24: Cancelled | M24: Amazon Logistics
A25: ORD0024 | B25: 11/2/2023 | C25: 11/5/2023 | E25: CUST028 | F25: PROD006 | G25: West | H25: 96 | I25: 5 | J25: 480 | K25: Amazon Pay | L25: Delivered | M25: Amazon Logistics
A26: ORD0025 | B26: 5/28/2023 | C26: 5/30/2023 | E26: CUST040 | F26: PROD002 | G26: South | H26: 43 | I26: 1 | J26: 43 | K26: Debit Card | L26: Delivered | M26: Amazon Logistics
A27: ORD0026 | B27: 10/15/2023 | C27: 10/21/2023 | E27: CUST027 | F27: PROD022 | G27: South | H27: 64 | I27: 4 | J27: 256 | K27: Debit Card | L27: Delivered | M27: USPS
A28: ORD0027 | B28: 1/16/2023 | E28: CUST018 | F28: PROD008 | G28: South | H28: 70 | I28: 2 | J28: 140 | K28: Amazon Pay | L28: In Transit | M28: Amazon Logistics
A29: ORD0028 | B29: 10/9/2023 | E29: CUST018 | F29: PROD018 | G29: Central | H29: 97 | I29: 3 | J29: 291 | K29: Credit Card | L29: In Transit | M29: Amazon Logistics
A30: ORD0029 | B30: 10/7/2023 | D30: 10/10/2023 | E30: CUST007 | F30: PROD021 | G30: East | H30: 37 | I30: 3 | J30: 111 | K30: Apple Pay | L30: Cancelled | M30: DHL
A31: ORD0030 | B31: 2/14/2023 | E31: CUST008 | F31: PROD008 | G31: North | H31: 69 | I31: 5 | J31: 345 | K31: Amazon Pay | L31: In Transit | M31: Amazon Logistics
A32: ORD0031 | B32: 3/26/2023 | E32: CUST014 | F32: PROD002 | G32: North | H32: 42 | I32: 5 | J32: 210 | K32: Amazon Pay | L32: In Transit | M32: UPS
A33: ORD0032 | B33: 6/15/2023 | D33: 6/22/2023 | E33: CUST037 | F33: PROD009 | G33: East | H33: 11 | I33: 5 | J33: 55 | K33: Debit Card | L33: Cancelled | M33: FedEx
A34: ORD0033 | B34: 5/22/2023 | C34: 5/23/2023 | E34: CUST016 | F34: PROD005 | G34: South | H34: 27 | I34: 2 | J34: 54 | K34: Apple Pay | L34: Delivered | M34: USPS
A35: ORD0034 | B35: 11/20/2023 | E35: CUST025 | F35: PROD015 | G35: South | H35: 21 | I35: 1 | J35: 21 | K35: Amazon Pay | L35: In Transit | M35: DHL
A36: ORD0035 | B36: 12/22/2023 | C36: 12/26/2023 | E36: CUST032 | F36: PROD011 | G36: South | H36: 172 | I36: 1 | J36: 172 | K36: PayPal | L36: Delivered | M36: USPS
A37: ORD0036 | B37: 7/23/2023 | E37: CUST014 | F37: PROD016 | G37: North | H37: 212 | I37: 3 | J37: 636 | K37: Amazon Pay | L37: In Transit | M37: UPS
A38: ORD0037 | B38: 10/17/2023 | C38: 10/22/2023 | E38: CUST044 | F38: PROD002 | G38: East | H38: 41 | I38: 4 | J38: 164 | K38: Credit Card | L38: Delivered | M38: Amazon Logistics
A39: ORD0038 | B39: 8/22/2023 | D39: 8/24/2023 | E39: CUST028 | F39: PROD007 | G39: North | H39: 32 | I39: 2 | J39: 64 | K39: Debit Card | L39: Cancelled | M39: FedEx
A40: ORD0039 | B40: 12/2/2023 | E40: CUST024 | F40: PROD022 | G40: East | H40: 66 | I40: 2 | J40: 132 | K40: Apple Pay | L40: In Transit | M40: DHL
...

Sheet ProductMaster
A1: Product ID | B1: Product Name | C1: Category | D1: Cost Price | E1: Description
A2: PROD001 | B2: Smartphone | C2: Electronics | D2: 749 | E2: Latest model with 5G, dual SIM, and OLED display
A3: PROD002 | B3: Action Figure | C3: Toys | D3: 39 | E3: Collectible superhero action figure for ages 8+
A4: PROD003 | B4: Cookware Set | C4: Home | D4: 129 | E4: Non-stick 5-piece cookware set for daily use
A5: PROD004 | B5: Leg Set | C5: Toys | D5: 59 | E5: 300-piece creative building block toy set
A6: PROD005 | B6: T-Shirt | C6: Fashion | D6: 25 | E6: Cotton t-shirt, available in multiple colors
A7: PROD006 | B7: Shoes | C7: Fashion | D7: 89 | E7: Casual wear shoes for men and women
A8: PROD007 | B8: Puzzle | C8: Toys | D8: 29 | E8: 1000-piece jigsaw puzzle
A9: PROD008 | B9: Textbook | C9: Books | D9: 65 | E9: University-level textbook on computer science
A10: PROD009 | B10: Magazine | C10: Books | D10: 10 | E10: Monthly lifestyle magazine
A11: PROD010 | B11: Jeans | C11: Fashion | D11: 55 | E11: Slim fit denim jeans with stretch
A12: PROD011 | B12: Headphones | C12: Electronics | D12: 159 | E12: Wireless noise-cancelling over-ear headphones
A13: PROD012 | B13: Lamp | C13: Home | D13: 42 | E13: LED desk lamp with dimmable light
... A23: PROD022 | B23: Backpack | C23: Fashion | D23: 60 | E23: Waterproof backpack with laptop compartment

Sheet CustomerMaster
A1: Customer ID | B1: Customer Name | C1: Customer Type | D1: City | E1: State
A2: CUST001 | B2: James Miller | C2: Business | D2: New York | E2: New York
A3: CUST002 | B3: Emily Johnson | C3: Prime | D3: Seattle | E3: Washington
A4: CUST003 | B4: Ethan Davis | C4: Prime | D4: Austin | E4: Texas
A5: CUST004 | B5: Noah Wilson | C5: Prime | D5: San Francisco | E5: California
A6: CUST005 | B6: Olivia Martinez | C6: Prime | D6: Seattle | E6: Washington
A7: CUST006 | B7: Ava Robinson | C7: Prime | D7: Chicago | E7: Illinois
A8: CUST007 | B8: Liam Walker | C8: Prime | D8: San Francisco | E8: California
A9: CUST008 | B9: Harper Young | C9: Business | D9: Dallas | E9: Texas
A10: CUST009 | B10: Jackson Allen | C10: Business | D10: Seattle | E10: Washington
A11: CUST010 | B11: Charlotte Harris | C11: Prime | D11: Chicago | E11: Illinois
A12: CUST011 | B12: Mason Hall | C12: Business | D12: Miami | E12: Florida
... A50: CUST049 | B50: Hazel Gray | C50: Business | D50: Chicago | E50: Illinois

Sheet RegionGoals
A1: Region | B1: Sales Target
A2: Central | B2: 97500
A3: East | B3: 50500
A4: North | B4: 105000
A5: South | B5: 91500
A6: West | B6: 90750

Sheet AmazonSales_Clean
A1: Order ID | B1: Order Date | C1: Month | D1: Delivery Date | E1: Cancel Date | F1: Customer ID | G1: Product ID | H1: Region | I1: Sale Price/Unit | J1: Quantity | K1: Sales Amount | L1: Payment Method | M1: Delivery Status | N1: Fulfillment Partner | O1: Product Category | P1: Order Status | Q1: Delivery Days | R1: Delivery Performance | S1: Effective Sales | T1: Customer Name
A2: ORD0001 | B2: 12/31/2023 | C2: =TEXT(B2,"mmm") -> Dec | E2: 1/2/2024 | F2: CUST021 | G2: PROD012 | H2: North | I2: 44 | J2: 1 | K2: 44 | L2: Apple Pay | M2: Cancelled | N2: DHL | O2: =_xlfn.XLOOKUP(G2,ProductMaster!$A$2:$A$23,ProductMaster!$C$2:$C$23,"Not Found") -> Home | P2: =IF(M2="Cancelled","Cancelled",IF(M2="delivered","Delivered","Active")) -> Cancelled | Q2: =IF(M2="delivered",D2-B2,"") | R2: =IF(M2="Delivered",IF(D2-B2<=2,"Fast","Slow"),"Not Delivered") -> Not Delivered | S2: =IF(M2="delivered",K2,0) -> 0 | T2: =_xlfn.XLOOKUP(F2,CustomerMaster!$A$2:$A$50,CustomerMaster!$B$2:$B$50,"Not Found") -> Zoe Mitchell
A3: ORD0002 | B3: 2/22/2023 | C3: =TEXT(B3,"mmm") -> Feb | D3: 2/24/2023 | F3: CUST029 | G3: PROD018 | H3: East | I3: 96 | J3: 4 | K3: 384 | L3: Credit Card | M3: Delivered | N3: DHL | O3: =_xlfn.XLOOKUP(G3,ProductMaster!$A$2:$A$23,ProductMaster!$C$2:$C$23,"Not Found") -> Toys | P3: =IF(M3="Cancelled","Cancelled",IF(M3="delivered","Delivered","Active")) -> Delivered | Q3: =IF(M3="delivered",D3-B3,"") -> 2 | R3: =IF(M3="Delivered",IF(D3-B3<=2,"Fast","Slow"),"Not Delivered") -> Fast | S3: =IF(M3="delivered",K3,0) -> 384 | T3: =_xlfn.XLOOKUP(F3,CustomerMaster!$A$2:$A$50,CustomerMaster!$B$2:$B$50,"Not Found") -> Ava White
A4: ORD0003 | B4: 10/11/2023 | C4: =TEXT(B4,"mmm") -> Oct | F4: CUST021 | G4: PROD013 | H4: South | I4: 194 | J4: 4 | K4: 776 | L4: Credit Card | M4: In Transit | N4: USPS | O4: =_xlfn.XLOOKUP(G4,ProductMaster!$A$2:$A$23,ProductMaster!$C$2:$C$23,"Not Found") -> Home | P4: =IF(M4="Cancelled","Cancelled",IF(M4="delivered","Delivered","Active")) -> Active | Q4: =IF(M4="delivered",D4-B4,"") | R4: =IF(M4="Delivered",IF(D4-B4<=2,"Fast","Slow"),"Not Delivered") -> Not Delivered | S4: =IF(M4="delivered",K4,0) -> 0 | T4: =_xlfn.XLOOKUP(F4,CustomerMaster!$A$2:$A$50,CustomerMaster!$B$2:$B$50,"Not Found") -> Zoe Mitchell
A5: ORD0004 | B5: 5/5/2023 | C5: =TEXT(B5,"mmm") -> May | E5: 5/11/2023 | F5: CUST044 | G5: PROD013 | H5: North | I5: 196 | J5: 3 | K5: 196 | L5: PayPal | M5: Cancelled | N5: UPS | O5: =_xlfn.XLOOKUP(G5,ProductMaster!$A$2:$A$23,ProductMaster!$C$2:$C$23,"Not Found") -> Home | P5: =IF(M5="Cancelled","Cancelled",IF(M5="delivered","Delivered","Active")) -> Cancelled | Q5: =IF(M5="delivered",D5-B5,"") | R5: =IF(M5="Delivered",IF(D5-B5<=2,"Fast","Slow"),"Not Delivered") -> Not Delivered | S5: =IF(M5="delivered",K5,0) -> 0 | T5: =_xlfn.XLOOKUP(F5,CustomerMaster!$A$2:$A$50,CustomerMaster!$B$2:$B$50,"Not Found") -> Grace Ward
A6: ORD0005 | B6: 2/2/2023 | C6: =TEXT(B6,"mmm") -> Feb | D6: 2/5/2023 | F6: CUST027 | G6: PROD010 | H6: North | I6: 59 | J6: 1 | K6: 59 | L6: PayPal | M6: Delivered | N6: Amazon Logistics | O6: =_xlfn.XLOOKUP(G6,ProductMaster!$A$2:$A$23,ProductMaster!$C$2:$C$23,"Not Found") -> Fashion | P6: =IF(M6="Cancelled","Cancelled",IF(M6="delivered","Delivered","Active")) -> Delivered | Q6: =IF(M6="delivered",D6-B6,"") -> 3 | R6: =IF(M6="Delivered",IF(D6-B6<=2,"Fast","Slow"),"Not Delivered") -> Slow | S6: =IF(M6="delivered",K6,0) -> 59 | T6: =_xlfn.XLOOKUP(F6,CustomerMaster!$A$2:$A$50,CustomerMaster!$B$2:$B$50,"Not Found") -> Hazel Brooks
A7: ORD0006 | B7: 11/1/2023 | C7: =TEXT(B7,"mmm") -> Nov | E7: 11/2/2023 | F7: CUST009 | G7: PROD010 | H7: North | I7: 58 | J7: 4 | K7: 58 | L7: Amazon Pay | M7: Cancelled | N7: DHL | O7: =_xlfn.XLOOKUP(G7,ProductMaster!$A$2:$A$23,ProductMaster!$C$2:$C$23,"Not Found") -> Fashion | P7: =IF(M7="Cancelled","Cancelled",IF(M7="delivered","Delivered","Active")) -> Cancelled | Q7: =IF(M7="delivered",D7-B7,"") | R7: =IF(M7="Delivered",IF(D7-B7<=2,"Fast","Slow"),"Not Delivered") -> Not Delivered | S7: =IF(M7="delivered",K7,0) -> 0 | T7: =_xlfn.XLOOKUP(F7,CustomerMaster!$A$2:$A$50,CustomerMaster!$B$2:$B$50,"Not Found") -> Jackson Allen
A8: ORD0007 | B8: 8/14/2023 | C8: =TEXT(B8,"mmm") -> Aug | E8: 8/18/2023 | F8: CUST042 | G8: PROD020 | H8: Central | I8: 105 | J8: 3 | K8: 105 | L8: Debit Card | M8: Cancelled | N8: DHL | O8: =_xlfn.XLOOKUP(G8,ProductMaster!$A$2:$A$23,ProductMaster!$C$2:$C$23,"Not Found") -> Electronics | P8: =IF(M8="Cancelled","Cancelled",IF(M8="delivered","Delivered","Active")) -> Cancelled | Q8: =IF(M8="delivered",D8-B8,"") | R8: =IF(M8="Delivered",IF(D8-B8<=2,"Fast","Slow"),"Not Delivered") -> Not Delivered | S8: =IF(M8="delivered",K8,0) -> 0 | T8: =_xlfn.XLOOKUP(F8,CustomerMaster!$A$2:$A$50,CustomerMaster!$B$2:$B$50,"Not Found") -> Noah Wilson
A9: ORD0008 | B9: 4/1/2023 | C9: =TEXT(B9,"mmm") -> Apr | E9: 4/6/2023 | F9: CUST019 | G9: PROD021 | H9: West | I9: 37 | J9: 5 | K9: 37 | L9: PayPal | M9: Cancelled | N9: DHL | O9: =_xlfn.XLOOKUP(G9,ProductMaster!$A$2:$A$23,ProductMaster!$C$2:$C$23,"Not Found") -> Home | P9: =IF(M9="Cancelled","Cancelled",IF(M9="delivered","Delivered","Active")) -> Cancelled | Q9: =IF(M9="delivered",D9-B9,"") | R9: =IF(M9="Delivered",IF(D9-B9<=2,"Fast","Slow"),"Not Delivered") -> Not Delivered | S9: =IF(M9="delivered",K9,0) -> 0 | T9: =_xlfn.XLOOKUP(F9,CustomerMaster!$A$2:$A$50,CustomerMaster!$B$2:$B$50,"Not Found") -> Ava Robinson
A10: ORD0009 | B10: 7/21/2023 | C10: =TEXT(B10,"mmm") -> Jul | F10: CUST013 | G10: PROD019 | H10: Central | I10: 44 | J10: 2 | K10: 88 | L10: Credit Card | M10: In Transit | N10: Amazon Logistics | O10: =_xlfn.XLOOKUP(G10,ProductMaster!$A$2:$A$23,ProductMaster!$C$2:$C$23,"Not Found") -> Fashion | P10: =IF(M10="Cancelled","Cancelled",IF(M10="delivered","Delivered","Active")) -> Active | Q10: =IF(M10="delivered",D10-B10,"") | R10: =IF(M10="Delivered",IF(D10-B10<=2,"Fast","Slow"),"Not Delivered") -> Not Delivered | S10: =IF(M10="delivered",K10,0) -> 0 | T10: =_xlfn.XLOOKUP(F10,CustomerMaster!$A$2:$A$50,CustomerMaster!$B$2:$B$50,"Not Found") -> Olivia Martinez
A11: ORD0010 | B11: 12/29/2023 | C11: =TEXT(B11,"mmm") -> Dec | F11: CUST019 | G11: PROD003 | H11: South | I11: 141 | J11: 4 | K11: 564 | L11: Debit Card | M11: In Transit | N11: DHL | O11: =_xlfn.XLOOKUP(G11,ProductMaster!$A$2:$A$23,ProductMaster!$C$2:$C$23,"Not Found") -> Home | P11: =IF(M11="Cancelled","Cancelled",IF(M11="delivered","Delivered","Active")) -> Active | Q11: =IF(M11="delivered",D11-B11,"") | R11: =IF(M11="Delivered",IF(D11-B11<=2,"Fast","Slow"),"Not Delivered") -> Not Delivered | S11: =IF(M11="delivered",K11,0) -> 0 | T11: =_xlfn.XLOOKUP(F11,CustomerMaster!$A$2:$A$50,CustomerMaster!$B$2:$B$50,"Not Found") -> Ava Robinson
A12: ORD0011 | B12: 5/4/2023 | C12: =TEXT(B12,"mmm") -> May | E12: 5/8/2023 | F12: CUST046 | G12: PROD014 | H12: South | I12: 249 | J12: 1 | K12: 249 | L12: Amazon Pay | M12: Cancelled | N12: USPS | O12: =_xlfn.XLOOKUP(G12,ProductMaster!$A$2:$A$23,ProductMaster!$C$2:$C$23,"Not Found") -> Electronics | P12: =IF(M12="Cancelled","Cancelled",IF(M12="delivered","Delivered","Active")) -> Cancelled | Q12: =IF(M12="delivered",D12-B12,"") | R12: =IF(M12="Delivered",IF(D12-B12<=2,"Fast","Slow"),"Not Delivered") -> Not Delivered | S12: =IF(M12="delivered",K12,0) -> 0 | T12: =_xlfn.XLOOKUP(F12,CustomerMaster!$A$2:$A$50,CustomerMaster!$B$2:$B$50,"Not Found") -> Emily Johnson
A13: ORD0012 | B13: 7/25/2023 | C13: =TEXT(B13,"mmm") -> Jul | F13: CUST045 | G13: PROD014 | H13: Central | I13: 247 | J13: 3 | K13: 741 | L13: Amazon Pay | M13: In Transit | N13: FedEx | O13: =_xlfn.XLOOKUP(G13,ProductMaster!$A$2:$A$23,ProductMaster!$C$2:$C$23,"Not Found") -> Electronics | P13: =IF(M13="Cancelled","Cancelled",IF(M13="delivered","Delivered","Active")) -> Active | Q13: =IF(M13="delivered",D13-B13,"") | R13: =IF(M13="Delivered",IF(D13-B13<=2,"Fast","Slow"),"Not Delivered") -> Not Delivered | S13: =IF(M13="delivered",K13,0) -> 0 | T13: =_xlfn.XLOOKUP(F13,CustomerMaster!$A$2:$A$50,CustomerMaster!$B$2:$B$50,"Not Found") -> Emily Johnson
A14: ORD0013 | B14: 2/25/2023 | C14: =TEXT(B14,"mmm") -> Feb | E14: 2/28/2023 | F14: CUST023 | G14: PROD006 | H14: Central | I14: 96 | J14: 1 | K14: 96 | L14: Apple Pay | M14: Cancelled | N14: Amazon Logistics | O14: =_xlfn.XLOOKUP(G14,ProductMaster!$A$2:$A$23,ProductMaster!$C$2:$C$23,"Not Found") -> Fashion | P14: =IF(M14="Cancelled","Cancelled",IF(M14="delivered","Delivered","Active")) -> Cancelled | Q14: =IF(M14="delivered",D14-B14,"") | R14: =IF(M14="Delivered",IF(D14-B14<=2,"Fast","Slow"),"Not Delivered") -> Not Delivered | S14: =IF(M14="delivered",K14,0) -> 0 | T14: =_xlfn.XLOOKUP(F14,CustomerMaster!$A$2:$A$50,CustomerMaster!$B$2:$B$50,"Not Found") -> Charlotte Reed
A15: ORD0014 | B15: 2/24/2023 | C15: =TEXT(B15,"mmm") -> Feb | E15: 2/25/2023 | F15: CUST033 | G15: PROD017 | H15: West | I15: 74 | J15: 5 | K15: 74 | L15: Apple Pay | M15: Cancelled | N15: Amazon Logistics | O15: =_xlfn.XLOOKUP(G15,ProductMaster!$A$2:$A$23,ProductMaster!$C$2:$C$23,"Not Found") -> Electronics | P15: =IF(M15="Cancelled","Cancelled",IF(M15="delivered","Delivered","Active")) -> Cancelled | Q15: =IF(M15="delivered",D15-B15,"") | R15: =IF(M15="Delivered",IF(D15-B15<=2,"Fast","Slow"),"Not Delivered") -> Not Delivered | S15: =IF(M15="delivered",K15,0) -> 0 | T15: =_xlfn.XLOOKUP(F15,CustomerMaster!$A$2:$A$50,CustomerMaster!$B$2:$B$50,"Not Found") -> Hazel Rivera
A16: ORD0015 | B16: 8/26/2023 | C16: =TEXT(B16,"mmm") -> Aug | E16: 9/2/2023 | F16: CUST033 | G16: PROD005 | H16: South | I16: 27 | J16: 1 | K16: 27 | L16: Credit Card | M16: Cancelled | N16: Amazon Logistics | O16: =_xlfn.XLOOKUP(G16,ProductMaster!$A$2:$A$23,ProductMaster!$C$2:$C$23,"Not Found") -> Fashion | P16: =IF(M16="Cancelled","Cancelled",IF(M16="delivered","Delivered","Active")) -> Cancelled | Q16: =IF(M16="delivered",D16-B16,"") | R16: =IF(M16="Delivered",IF(D16-B16<=2,"Fast","Slow"),"Not Delivered") -> Not Delivered | S16: =IF(M16="delivered",K16,0) -> 0 | T16: =_xlfn.XLOOKUP(F16,CustomerMaster!$A$2:$A$50,CustomerMaster!$B$2:$B$50,"Not Found") -> Hazel Rivera
A17: ORD0016 | B17: 2/13/2023 | C17: =TEXT(B17,"mmm") -> Feb | F17: CUST047 | G17: PROD005 | H17: South | I17: 27 | J17: 3 | K17: 81 | L17: Debit Card | M17: In Transit | N17: Amazon Logistics | O17: =_xlfn.XLOOKUP(G17,ProductMaster!$A$2:$A$23,ProductMaster!$C$2:$C$23,"Not Found") -> Fashion | P17: =IF(M17="Cancelled","Cancelled",IF(M17="delivered","Delivered","Active")) -> Active | Q17: =IF(M17="delivered",D17-B17,"") | R17: =IF(M17="Delivered",IF(D17-B17<=2,"Fast","Slow"),"Not Delivered") -> Not Delivered | S17: =IF(M17="delivered",K17,0) -> 0 | T17: =_xlfn.XLOOKUP(F17,CustomerMaster!$A$2:$A$50,CustomerMaster!$B$2:$B$50,"Not Found") -> Scarlett Murphy
A18: ORD0017 | B18: 6/28/2023 | C18: =TEXT(B18,"mmm") -> Jun | D18: 7/1/2023 | F18: CUST045 | G18: PROD015 | H18: East | I18: 21 | J18: 3 | K18: 63 | L18: Credit Card | M18: Delivered | N18: DHL | O18: =_xlfn.XLOOKUP(G18,ProductMaster!$A$2:$A$23,ProductMaster!$C$2:$C$23,"Not Found") -> Books | P18: =IF(M18="Cancelled","Cancelled",IF(M18="delivered","Delivered","Active")) -> Delivered | Q18: =IF(M18="delivered",D18-B18,"") -> 3 | R18: =IF(M18="Delivered",IF(D18-B18<=2,"Fast","Slow"),"Not Delivered") -> Slow | S18: =IF(M18="delivered",K18,0) -> 63 | T18: =_xlfn.XLOOKUP(F18,CustomerMaster!$A$2:$A$50,CustomerMaster!$B$2:$B$50,"Not Found") -> Emily Johnson
A19: ORD0018 | B19: 11/28/2023 | C19: =TEXT(B19,"mmm") -> Nov | F19: CUST011 | G19: PROD008 | H19: West | I19: 70 | J19: 5 | K19: 350 | L19: PayPal | M19: In Transit | N19: Amazon Logistics | O19: =_xlfn.XLOOKUP(G19,ProductMaster!$A$2:$A$23,ProductMaster!$C$2:$C$23,"Not Found") -> Books | P19: =IF(M19="Cancelled","Cancelled",IF(M19="delivered","Delivered","Active")) -> Active | Q19: =IF(M19="delivered",D19-B19,"") | R19: =IF(M19="Delivered",IF(D19-B19<=2,"Fast","Slow"),"Not Delivered") -> Not Delivered | S19: =IF(M19="delivered",K19,0) -> 0 | T19: =_xlfn.XLOOKUP(F19,CustomerMaster!$A$2:$A$50,CustomerMaster!$B$2:$B$50,"Not Found") -> Mason Hall
A20: ORD0019 | B20: 8/25/2023 | C20: =TEXT(B20,"mmm") -> Aug | F20: CUST041 | G20: PROD006 | H20: South | I20: 94 | J20: 4 | K20: 376 | L20: Credit Card | M20: In Transit | N20: USPS | O20: =_xlfn.XLOOKUP(G20,ProductMaster!$A$2:$A$23,ProductMaster!$C$2:$C$23,"Not Found") -> Fashion | P20: =IF(M20="Cancelled","Cancelled",IF(M20="delivered","Delivered","Active")) -> Active | Q20: =IF(M20="delivered",D20-B20,"") | R20: =IF(M20="Delivered",IF(D20-B20<=2,"Fast","Slow"),"Not Delivered") -> Not Delivered | S20: =IF(M20="delivered",K20,0) -> 0 | T20: =_xlfn.XLOOKUP(F20,CustomerMaster!$A$2:$A$50,CustomerMaster!$B$2:$B$50,"Not Found") -> Jacob Price
A21: ORD0020 | B21: 4/12/2023 | C21: =TEXT(B21,"mmm") -> Apr | F21: CUST025 | G21: PROD001 | H21: North | I21: 813 | J21: 2 | K21: 1626 | L21: Credit Card | M21: In Transit | N21: FedEx | O21: =_xlfn.XLOOKUP(G21,ProductMaster!$A$2:$A$23,ProductMaster!$C$2:$C$23,"Not Found") -> Electronics | P21: =IF(M21="Cancelled","Cancelled",IF(M21="delivered","Delivered","Active")) -> Active | Q21: =IF(M21="delivered",D21-B21,"") | R21: =IF(M21="Delivered",IF(D21-B21<=2,"Fast","Slow"),"Not Delivered") -> Not Delivered | S21: =IF(M21="delivered",K21,0) -> 0 | T21: =_xlfn.XLOOKUP(F21,CustomerMaster!$A$2:$A$50,CustomerMaster!$B$2:$B$50,"Not Found") -> Emma King
A22: ORD0021 | B22: 10/2/2023 | C22: =TEXT(B22,"mmm") -> Oct | F22: CUST013 | G22: PROD015 | H22: Central | I22: 21 | J22: 4 | K22: 84 | L22: PayPal | M22: In Transit | N22: Amazon Logistics | O22: =_xlfn.XLOOKUP(G22,ProductMaster!$A$2:$A$23,ProductMaster!$C$2:$C$23,"Not Found") -> Books | P22: =IF(M22="Cancelled","Cancelled",IF(M22="delivered","Delivered","Active")) -> Active | Q22: =IF(M22="delivered",D22-B22,"") | R22: =IF(M22="Delivered",IF(D22-B22<=2,"Fast","Slow"),"Not Delivered") -> Not Delivered | S22: =IF(M22="delivered",K22,0) -> 0 | T22: =_xlfn.XLOOKUP(F22,CustomerMaster!$A$2:$A$50,CustomerMaster!$B$2:$B$50,"Not Found") -> Olivia Martinez
A23: ORD0022 | B23: 11/9/2023 | C23: =TEXT(B23,"mmm") -> Nov | F23: CUST023 | G23: PROD012 | H23: West | I23: 46 | J23: 5 | K23: 230 | L23: PayPal | M23: In Transit | N23: USPS | O23: =_xlfn.XLOOKUP(G23,ProductMaster!$A$2:$A$23,ProductMaster!$C$2:$C$23,"Not Found") -> Home | P23: =IF(M23="Cancelled","Cancelled",IF(M23="delivered","Delivered","Active")) -> Active | Q23: =IF(M23="delivered",D23-B23,"") | R23: =IF(M23="Delivered",IF(D23-B23<=2,"Fast","Slow"),"Not Delivered") -> Not Delivered | S23: =IF(M23="delivered",K23,0) -> 0 | T23: =_xlfn.XLOOKUP(F23,CustomerMaster!$A$2:$A$50,CustomerMaster!$B$2:$B$50,"Not Found") -> Charlotte Reed
A24: ORD0023 | B24: 2/13/2023 | C24: =TEXT(B24,"mmm") -> Feb | E24: 2/14/2023 | F24: CUST016 | G24: PROD010 | H24: West | I24: 58 | J24: 3 | K24: 58 | L24: Amazon Pay | M24: Cancelled | N24: Amazon Logistics | O24: =_xlfn.XLOOKUP(G24,ProductMaster!$A$2:$A$23,ProductMaster!$C$2:$C$23,"Not Found") -> Fashion | P24: =IF(M24="Cancelled","Cancelled",IF(M24="delivered","Delivered","Active")) -> Cancelled | Q24: =IF(M24="delivered",D24-B24,"") | R24: =IF(M24="Delivered",IF(D24-B24<=2,"Fast","Slow"),"Not Delivered") -> Not Delivered | S24: =IF(M24="delivered",K24,0) -> 0 | T24: =_xlfn.XLOOKUP(F24,CustomerMaster!$A$2:$A$50,CustomerMaster!$B$2:$B$50,"Not Found") -> Elijah Lewis
A25: ORD0024 | B25: 11/2/2023 | C25: =TEXT(B25,"mmm") -> Nov | D25: 11/5/2023 | F25: CUST028 | G25: PROD006 | H25: West | I25: 96 | J25: 5 | K25: 480 | L25: Amazon Pay | M25: Delivered | N25: Amazon Logistics | O25: =_xlfn.XLOOKUP(G25,ProductMaster!$A$2:$A$23,ProductMaster!$C$2:$C$23,"Not Found") -> Fashion | P25: =IF(M25="Cancelled","Cancelled",IF(M25="delivered","Delivered","Active")) -> Delivered | Q25: =IF(M25="delivered",D25-B25,"") -> 3 | R25: =IF(M25="Delivered",IF(D25-B25<=2,"Fast","Slow"),"Not Delivered") -> Slow | S25: =IF(M25="delivered",K25,0) -> 480 | T25: =_xlfn.XLOOKUP(F25,CustomerMaster!$A$2:$A$50,CustomerMaster!$B$2:$B$50,"Not Found") -> Lily Bennett
A26: ORD0025 | B26: 5/28/2023 | C26: =TEXT(B26,"mmm") -> May | D26: 5/30/2023 | F26: CUST040 | G26: PROD002 | H26: South | I26: 43 | J26: 1 | K26: 43 | L26: Debit Card | M26: Delivered | N26: Amazon Logistics | O26: =_xlfn.XLOOKUP(G26,ProductMaster!$A$2:$A$23,ProductMaster!$C$2:$C$23,"Not Found") -> Toys | P26: =IF(M26="Cancelled","Cancelled",IF(M26="delivered","Delivered","Active")) -> Delivered | Q26: =IF(M26="delivered",D26-B26,"") -> 2 | R26: =IF(M26="Delivered",IF(D26-B26<=2,"Fast","Slow"),"Not Delivered") -> Fast | S26: =IF(M26="delivered",K26,0) -> 43 | T26: =_xlfn.XLOOKUP(F26,CustomerMaster!$A$2:$A$50,CustomerMaster!$B$2:$B$50,"Not Found") -> Benjamin Clark
A27: ORD0026 | B27: 10/15/2023 | C27: =TEXT(B27,"mmm") -> Oct | D27: 10/21/2023 | F27: CUST027 | G27: PROD022 | H27: South | I27: 64 | J27: 4 | K27: 256 | L27: Debit Card | M27: Delivered | N27: USPS | O27: =_xlfn.XLOOKUP(G27,ProductMaster!$A$2:$A$23,ProductMaster!$C$2:$C$23,"Not Found") -> Fashion | P27: =IF(M27="Cancelled","Cancelled",IF(M27="delivered","Delivered","Active")) -> Delivered | Q27: =IF(M27="delivered",D27-B27,"") -> 6 | R27: =IF(M27="Delivered",IF(D27-B27<=2,"Fast","Slow"),"Not Delivered") -> Slow | S27: =IF(M27="delivered",K27,0) -> 256 | T27: =_xlfn.XLOOKUP(F27,CustomerMaster!$A$2:$A$50,CustomerMaster!$B$2:$B$50,"Not Found") -> Hazel Brooks
A28: ORD0027 | B28: 1/16/2023 | C28: =TEXT(B28,"mmm") -> Jan | F28: CUST018 | G28: PROD008 | H28: South | I28: 70 | J28: 2 | K28: 140 | L28: Amazon Pay | M28: In Transit | N28: Amazon Logistics | O28: =_xlfn.XLOOKUP(G28,ProductMaster!$A$2:$A$23,ProductMaster!$C$2:$C$23,"Not Found") -> Books | P28: =IF(M28="Cancelled","Cancelled",IF(M28="delivered","Delivered","Active")) -> Active | Q28: =IF(M28="delivered",D28-B28,"") | R28: =IF(M28="Delivered",IF(D28-B28<=2,"Fast","Slow"),"Not Delivered") -> Not Delivered | S28: =IF(M28="delivered",K28,0) -> 0 | T28: =_xlfn.XLOOKUP(F28,CustomerMaster!$A$2:$A$50,CustomerMaster!$B$2:$B$50,"Not Found") -> Grace Scott
A29: ORD0028 | B29: 10/9/2023 | C29: =TEXT(B29,"mmm") -> Oct | F29: CUST018 | G29: PROD018 | H29: Central | I29: 97 | J29: 3 | K29: 291 | L29: Credit Card | M29: In Transit | N29: Amazon Logistics | O29: =_xlfn.XLOOKUP(G29,ProductMaster!$A$2:$A$23,ProductMaster!$C$2:$C$23,"Not Found") -> Toys | P29: =IF(M29="Cancelled","Cancelled",IF(M29="delivered","Delivered","Active")) -> Active | Q29: =IF(M29="delivered",D29-B29,"") | R29: =IF(M29="Delivered",IF(D29-B29<=2,"Fast","Slow"),"Not Delivered") -> Not Delivered | S29: =IF(M29="delivered",K29,0) -> 0 | T29: =_xlfn.XLOOKUP(F29,CustomerMaster!$A$2:$A$50,CustomerMaster!$B$2:$B$50,"Not Found") -> Grace Scott
A30: ORD0029 | B30: 10/7/2023 | C30: =TEXT(B30,"mmm") -> Oct | E30: 10/10/2023 | F30: CUST007 | G30: PROD021 | H30: East | I30: 37 | J30: 3 | K30: 37 | L30: Apple Pay | M30: Cancelled | N30: DHL | O30: =_xlfn.XLOOKUP(G30,ProductMaster!$A$2:$A$23,ProductMaster!$C$2:$C$23,"Not Found") -> Home | P30: =IF(M30="Cancelled","Cancelled",IF(M30="delivered","Delivered","Active")) -> Cancelled | Q30: =IF(M30="delivered",D30-B30,"") | R30: =IF(M30="Delivered",IF(D30-B30<=2,"Fast","Slow"),"Not Delivered") -> Not Delivered | S30: =IF(M30="delivered",K30,0) -> 0 | T30: =_xlfn.XLOOKUP(F30,CustomerMaster!$A$2:$A$50,CustomerMaster!$B$2:$B$50,"Not Found") -> Liam Walker
A31: ORD0030 | B31: 2/14/2023 | C31: =TEXT(B31,"mmm") -> Feb | F31: CUST008 | G31: PROD008 | H31: North | I31: 69 | J31: 5 | K31: 345 | L31: Amazon Pay | M31: In Transit | N31: Amazon Logistics | O31: =_xlfn.XLOOKUP(G31,ProductMaster!$A$2:$A$23,ProductMaster!$C$2:$C$23,"Not Found") -> Books | P31: =IF(M31="Cancelled","Cancelled",IF(M31="delivered","Delivered","Active")) -> Active | Q31: =IF(M31="delivered",D31-B31,"") | R31: =IF(M31="Delivered",IF(D31-B31<=2,"Fast","Slow"),"Not Delivered") -> Not Delivered | S31: =IF(M31="delivered",K31,0) -> 0 | T31: =_xlfn.XLOOKUP(F31,CustomerMaster!$A$2:$A$50,CustomerMaster!$B$2:$B$50,"Not Found") -> Harper Young
A32: ORD0031 | B32: 3/26/2023 | C32: =TEXT(B32,"mmm") -> Mar | F32: CUST014 | G32: PROD002 | H32: North | I32: 42 | J32: 5 | K32: 210 | L32: Amazon Pay | M32: In Transit | N32: UPS | O32: =_xlfn.XLOOKUP(G32,ProductMaster!$A$2:$A$23,ProductMaster!$C$2:$C$23,"Not Found") -> Toys | P32: =IF(M32="Cancelled","Cancelled",IF(M32="delivered","Delivered","Active")) -> Active | Q32: =IF(M32="delivered",D32-B32,"") | R32: =IF(M32="Delivered",IF(D32-B32<=2,"Fast","Slow"),"Not Delivered") -> Not Delivered | S32: =IF(M32="delivered",K32,0) -> 0 | T32: =_xlfn.XLOOKUP(F32,CustomerMaster!$A$2:$A$50,CustomerMaster!$B$2:$B$50,"Not Found") -> Harper Young
A33: ORD0032 | B33: 6/15/2023 | C33: =TEXT(B33,"mmm") -> Jun | E33: 6/22/2023 | F33: CUST037 | G33: PROD009 | H33: East | I33: 11 | J33: 5 | K33: 11 | L33: Debit Card | M33: Cancelled | N33: FedEx | O33: =_xlfn.XLOOKUP(G33,ProductMaster!$A$2:$A$23,ProductMaster!$C$2:$C$23,"Not Found") -> Books | P33: =IF(M33="Cancelled","Cancelled",IF(M33="delivered","Delivered","Active")) -> Cancelled | Q33: =IF(M33="delivered",D33-B33,"") | R33: =IF(M33="Delivered",IF(D33-B33<=2,"Fast","Slow"),"Not Delivered") -> Not Delivered | S33: =IF(M33="delivered",K33,0) -> 0 | T33: =_xlfn.XLOOKUP(F33,CustomerMaster!$A$2:$A$50,CustomerMaster!$B$2:$B$50,"Not Found") -> Emily Johnson
A34: ORD0033 | B34: 5/22/2023 | C34: =TEXT(B34,"mmm") -> May | D34: 5/23/2023 | F34: CUST016 | G34: PROD005 | H34: South | I34: 27 | J34: 2 | K34: 54 | L34: Apple Pay | M34: Delivered | N34: USPS | O34: =_xlfn.XLOOKUP(G34,ProductMaster!$A$2:$A$23,ProductMaster!$C$2:$C$23,"Not Found") -> Fashion | P34: =IF(M34="Cancelled","Cancelled",IF(M34="delivered","Delivered","Active")) -> Delivered | Q34: =IF(M34="delivered",D34-B34,"") -> 1 | R34: =IF(M34="Delivered",IF(D34-B34<=2,"Fast","Slow"),"Not Delivered") -> Fast | S34: =IF(M34="delivered",K34,0) -> 54 | T34: =_xlfn.XLOOKUP(F34,CustomerMaster!$A$2:$A$50,CustomerMaster!$B$2:$B$50,"Not Found") -> Elijah Lewis
A35: ORD0034 | B35: 11/20/2023 | C35: =TEXT(B35,"mmm") -> Nov | F35: CUST025 | G35: PROD015 | H35: South | I35: 21 | J35: 1 | K35: 21 | L35: Amazon Pay | M35: In Transit | N35: DHL | O35: =_xlfn.XLOOKUP(G35,ProductMaster!$A$2:$A$23,ProductMaster!$C$2:$C$23,"Not Found") -> Books | P35: =IF(M35="Cancelled","Cancelled",IF(M35="delivered","Delivered","Active")) -> Active | Q35: =IF(M35="delivered",D35-B35,"") | R35: =IF(M35="Delivered",IF(D35-B35<=2,"Fast","Slow"),"Not Delivered") -> Not Delivered | S35: =IF(M35="delivered",K35,0) -> 0 | T35: =_xlfn.XLOOKUP(F35,CustomerMaster!$A$2:$A$50,CustomerMaster!$B$2:$B$50,"Not Found") -> Emma King
A36: ORD0035 | B36: 12/22/2023 | C36: =TEXT(B36,"mmm") -> Dec | D36: 12/26/2023 | F36: CUST032 | G36: PROD011 | H36: South | I36: 172 | J36: 1 | K36: 172 | L36: PayPal | M36: Delivered | N36: USPS | O36: =_xlfn.XLOOKUP(G36,ProductMaster!$A$2:$A$23,ProductMaster!$C$2:$C$23,"Not Found") -> Electronics | P36: =IF(M36="Cancelled","Cancelled",IF(M36="delivered","Delivered","Active")) -> Delivered | Q36: =IF(M36="delivered",D36-B36,"") -> 4 | R36: =IF(M36="Delivered",IF(D36-B36<=2,"Fast","Slow"),"Not Delivered") -> Slow | S36: =IF(M36="delivered",K36,0) -> 172 | T36: =_xlfn.XLOOKUP(F36,CustomerMaster!$A$2:$A$50,CustomerMaster!$B$2:$B$50,"Not Found") -> Luke Gray
A37: ORD0036 | B37: 7/23/2023 | C37: =TEXT(B37,"mmm") -> Jul | F37: CUST014 | G37: PROD016 | H37: North | I37: 212 | J37: 3 | K37: 636 | L37: Amazon Pay | M37: In Transit | N37: UPS | O37: =_xlfn.XLOOKUP(G37,ProductMaster!$A$2:$A$23,ProductMaster!$C$2:$C$23,"Not Found") -> Home | P37: =IF(M37="Cancelled","Cancelled",IF(M37="delivered","Delivered","Active")) -> Active | Q37: =IF(M37="delivered",D37-B37,"") | R37: =IF(M37="Delivered",IF(D37-B37<=2,"Fast","Slow"),"Not Delivered") -> Not Delivered | S37: =IF(M37="delivered",K37,0) -> 0 | T37: =_xlfn.XLOOKUP(F37,CustomerMaster!$A$2:$A$50,CustomerMaster!$B$2:$B$50,"Not Found") -> Harper Young
A38: ORD0037 | B38: 10/17/2023 | C38: =TEXT(B38,"mmm") -> Oct | D38: 10/22/2023 | F38: CUST044 | G38: PROD002 | H38: East | I38: 41 | J38: 4 | K38: 164 | L38: Credit Card | M38: Delivered | N38: Amazon Logistics | O38: =_xlfn.XLOOKUP(G38,ProductMaster!$A$2:$A$23,ProductMaster!$C$2:$C$23,"Not Found") -> Toys | P38: =IF(M38="Cancelled","Cancelled",IF(M38="delivered","Delivered","Active")) -> Delivered | Q38: =IF(M38="delivered",D38-B38,"") -> 5 | R38: =IF(M38="Delivered",IF(D38-B38<=2,"Fast","Slow"),"Not Delivered") -> Slow | S38: =IF(M38="delivered",K38,0) -> 164 | T38: =_xlfn.XLOOKUP(F38,CustomerMaster!$A$2:$A$50,CustomerMaster!$B$2:$B$50,"Not Found") -> Grace Ward
A39: ORD0038 | B39: 8/22/2023 | C39: =TEXT(B39,"mmm") -> Aug | E39: 8/24/2023 | F39: CUST028 | G39: PROD007 | H39: North | I39: 32 | J39: 2 | K39: 32 | L39: Debit Card | M39: Cancelled | N39: FedEx | O39: =_xlfn.XLOOKUP(G39,ProductMaster!$A$2:$A$23,ProductMaster!$C$2:$C$23,"Not Found") -> Toys | P39: =IF(M39="Cancelled","Cancelled",IF(M39="delivered","Delivered","Active")) -> Cancelled | Q39: =IF(M39="delivered",D39-B39,"") | R39: =IF(M39="Delivered",IF(D39-B39<=2,"Fast","Slow"),"Not Delivered") -> Not Delivered | S39: =IF(M39="delivered",K39,0) -> 0 | T39: =_xlfn.XLOOKUP(F39,CustomerMaster!$A$2:$A$50,CustomerMaster!$B$2:$B$50,"Not Found") -> Lily Bennett
A40: ORD0039 | B40: 12/2/2023 | C40: =TEXT(B40,"mmm") -> Dec | F40: CUST024 | G40: PROD022 | H40: East | I40: 66 | J40: 2 | K40: 132 | L40: Apple Pay | M40: In Transit | N40: DHL | O40: =_xlfn.XLOOKUP(G40,ProductMaster!$A$2:$A$23,ProductMaster!$C$2:$C$23,"Not Found") -> Fashion | P40: =IF(M40="Cancelled","Cancelled",IF(M40="delivered","Delivered","Active")) -> Active | Q40: =IF(M40="delivered",D40-B40,"") | R40: =IF(M40="Delivered",IF(D40-B40<=2,"Fast","Slow"),"Not Delivered") -> Not Delivered | S40: =IF(M40="delivered",K40,0) -> 0 | T40: =_xlfn.XLOOKUP(F40,CustomerMaster!$A$2:$A$50,CustomerMaster!$B$2:$B$50,"Not Found") -> Scarlett Murphy
...

Sheet Sheet2
L3: Row Labels | M3: Sum of Effective Sales
B4: Row Labels | C4: Count of Order Status | H4: Row Labels | I4: Sum of Effective Sales | L4: Central | M4: 3010
B5: Cancelled | C5: 30 | H5: Books | I5: 127 | L5: East | M5: 1842
B6: Delivered | C6: 34 | H6: Electronics | I6: 6126 | L6: North | M6: 4075
H7: Fashion | I7: 1376 | L7: South | M7: 1063
H8: Home | I8: 4203 | L8: West | M8: 3666
H9: Toys | I9: 1824
B16: Row Labels | C16: Sum of Effective Sales | I16: Row Labels | J16: Sum of Effective Sales
B17: Amazon Logistics | C17: 2234 | I17: Apr | J17: 0
B18: DHL | C18: 2365 | I18: Aug | J18: 0
B19: FedEx | C19: 1934 | I19: Dec | J19: 2767
B20: UPS | C20: 2578 | I20: Feb | J20: 1298
B21: USPS | C21: 4545 | I21: Jan | J21: 192
I22: Jul | J22: 459
I23: Jun | J23: 1669
I24: Mar | J24: 0
I25: May | J25: 97
I26: Nov | J26: 4810
I27: Oct | J27: 1070
I28: Sep | J28: 1294

Sheet PivotTable
A1: Payment Method | B1: (All)
A3: Row Labels | B3: Sum of Sales Amount | D3: Row Labels | E3: Average of Delivery Days | K3: Sum of Effective Sales | L3: Product Category
A4: Central | B4: 4656 | D4: Central | E4: 4.2 | K4: Row Labels | L4: Books | M4: Electronics | N4: Fashion | O4: Home | P4: Toys | Q4: Grand Total
A5: Books | B5: 84 | D5: East | E5: 4.25 | K5: Jan | L5: 22 | N5: 26 | O5: 144 | Q5: 192
A6: Electronics | B6: 2452 | D6: North | E6: 3.625 | K6: Feb | L6: 0 | M6: 0 | N6: 140 | O6: 774 | P6: 384 | Q6: 1298
A7: Fashion | B7: 210 | D7: South | E7: 3.3333333 | K7: Mar | N7: 0 | P7: 0 | Q7: 0
A8: Home | B8: 1515 | D8: West | E8: 3.4285714 | K8: Apr | M8: 0 | O8: 0 | Q8: 0
A9: Toys | B9: 395 | D9: Grand Total | E9: 3.7647059 | K9: May | L9: 0 | M9: 0 | N9: 54 | O9: 0 | P9: 43 | Q9: 97
A10: East | B10: 3459 | K10: Jun | L10: 63 | M10: 1606 | N10: 0 | O10: 0 | Q10: 1669
A11: Books | B11: 350 | K11: Jul | L11: 42 | M11: 104 | N11: 0 | O11: 0 | P11: 313 | Q11: 459
A12: Electronics | B12: 365 | K12: Aug | M12: 0 | N12: 0 | P12: 0 | Q12: 0
A13: Fashion | B13: 653 | D13: Row Labels | E13: Count of Order Status | K13: Sep | L13: 0 | M13: 692 | N13: 172 | O13: 430 | Q13: 1294
A14: Home | B14: 667 | D14: Cancelled | E14: 30 | K14: Oct | L14: 0 | N14: 461 | O14: 0 | P14: 609 | Q14: 1070
A15: Toys | B15: 1424 | D15: Delivered | E15: 34 | K15: Nov | L15: 0 | M15: 3260 | N15: 480 | O15: 1070 | Q15: 4810
A16: North | B16: 8051 | D16: In Transit | E16: 36 | K16: Dec | M16: 464 | N16: 43 | O16: 1785 | P16: 475 | Q16: 2767
A17: Books | B17: 464 | D17: Grand Total | E17: 100 | K17: Grand Total | L17: 127 | M17: 6126 | N17: 1376 | O17: 4203 | P17: 1824 | Q17: 13656
A18: Electronics | B18: 5530
A19: Fashion | B19: 411
A20: Home | B20: 1154
A21: Toys | B21: 492
A22: South | B22: 7135
A23: West | B23: 7317
A24: Grand Total | B24: 30618

Sheet  Advanced Reporting
A3: Count of Delivery Status | B3: Column Labels | I3: Row Labels | J3: Sum of Effective Sales
A4: Row Labels | B4: Active | C4: Cancelled | D4: Delivered | E4: Grand Total | F4: Cancellation Rate | I4: Central | J4: 3010
A5: Central | B5: 4 | C5: 5 | D5: 5 | E5: 14 | F5: =GETPIVOTDATA("[Measures].[Count of Delivery Status]",A3,"[Range].[Region]","[Range].[Region].&[Central]","[Range].[Order Status]","[Range].[Order Status].&[Cancelled]")/GETPIVOTDATA("[Measures].[Count of Delivery Status]",A3,"[Range].[Region]","[Range].[Region].&[Central]") -> 0.35714286 | I5: East | J5: 1842
A6: East | B6: 7 | C6: 3 | D6: 8 | E6: 18 | F6: =GETPIVOTDATA("[Measures].[Count of Delivery Status]",$A$3,"[Range].[Region]","[Range].[Region].&[East]","[Range].[Order Status]","[Range].[Order Status].&[Cancelled]")/GETPIVOTDATA("[Measures].[Count of Delivery Status]",$A$3,"[Range].[Region]","[Range].[Region].&[East]") -> 0.16666667 | I6: North | J6: 4075
A7: North | B7: 7 | C7: 10 | D7: 8 | E7: 25 | F7: =GETPIVOTDATA("[Measures].[Count of Delivery Status]",$A$3,"[Range].[Region]","[Range].[Region].&[North]","[Range].[Order Status]","[Range].[Order Status].&[Cancelled]")/GETPIVOTDATA("[Measures].[Count of Delivery Status]",$A$3,"[Range].[Region]","[Range].[Region].&[North]") -> 0.4 | I7: South | J7: 1063
A8: South | B8: 10 | C8: 4 | D8: 6 | E8: 20 | F8: =GETPIVOTDATA("[Measures].[Count of Delivery Status]",$A$3,"[Range].[Region]","[Range].[Region].&[South]","[Range].[Order Status]","[Range].[Order Status].&[Cancelled]")/GETPIVOTDATA("[Measures].[Count of Delivery Status]",$A$3,"[Range].[Region]","[Range].[Region].&[South]") -> 0.2 | I8: West | J8: 3666
A9: West | B9: 8 | C9: 8 | D9: 7 | E9: 23 | F9: =GETPIVOTDATA("[Measures].[Count of Delivery Status]",$A$3,"[Range].[Region]","[Range].[Region].&[West]","[Range].[Order Status]","[Range].[Order Status].&[Cancelled]")/GETPIVOTDATA("[Measures].[Count of Delivery Status]",$A$3,"[Range].[Region]","[Range].[Region].&[West]") -> 0.34782609 | I9: Grand Total | J9: 13656
A10: Grand Total | B10: 36 | C10: 30 | D10: 34 | E10: 100 | F10: =GETPIVOTDATA("[Measures].[Count of Delivery Status]",$A$3,"[Range].[Order Status]","[Range].[Order Status].&[Cancelled]")/GETPIVOTDATA("[Measures].[Count of Delivery Status]",$A$3) -> 0.3

Sheet KPI_Dashboard

Sheet Brainstorming Reflection
A4: 1. Most Successful Product Category :-
A6: Electronics is the top-performing category in terms of revenue.
A8: This indicates that Electronics is the most successful product in the dataset and contributes the largest share of sales revenue.
A10: Overall, Electronics generated ₹6126, which is the largest share of the total effective sales of ₹13,656.
A12: 2. Region with Highest Cancellation Rate :-
A14: The North region has the highest cancellation rate.
A16: The North region has the highest cancellation rate (40%), which suggests potential issues related to delivery delays, logistics management, or customer service in that region.
A18: 3. Orders Delivered Within 2 Days :-
A20: Orders where the delivery time was 2 days or less were counted.
A22: Total Orders Delivered Within 2 Days: 11
A23: This indicates that only a limited number of orders were delivered quickly, which shows there is room to improve delivery efficiency.
A25: 4. How XLOOKUP Simplifies Cross-Sheet Analysis :-
... A55: Providing customers with real-time tracking updates can reduce cancellations caused by uncertainty about delivery times.
